Workbook

Sheet 후원목록
A1: c1 | B1: 시간 | C1: 방송시간 | D1: 닉네임 | E1: 아이디 | F1: 후원스트리머 | G1: 후원스트리머아이디 | H1: 풍선종류 | I1: 개수 | J1: 원플원 | K1: 채팅
A2: 1 | B2: 46283.851 | C2: 0:00:00 | D2: 차은돌 | E2: ckxoghksdlek | F2: 체온 | G2: leeso0403 | H2: 별풍선 | I2: 10 | K2: 은채
A3: 2 | B3: 46283.853 | C3: 0:02:50 | D3: 뱀체온 | E3: ehdtjq3304 | F3: 체온 | G3: leeso0403 | H3: 별풍선 | I3: 100 | K3: 가즈아
A4: 3 | B4: 46283.854 | C4: 0:04:17 | D4: 차은돌 | E4: ckxoghksdlek | F4: 체온 | G4: leeso0403 | H4: 별풍선 | I4: 10 | K4: 30분 ㅅㅅ 온마
A5: 4 | B5: 46283.855 | C5: 0:05:08 | D5: #페라리 | E5: cash11111 | F5: 체온 | G5: leeso0403 | H5: 별풍선 | I5: 100 | K5: 온마
A6: 5 | B6: 46283.856 | C6: 0:05:57 | D6: 차은돌 | E6: ckxoghksdlek | F6: 체온 | G6: leeso0403 | H6: 별풍선 | I6: 10 | K6: 온마
A7: 6 | B7: 46283.856 | C7: 0:06:27 | D7: [은]부엉 | E7: npeter7544 | F7: 체온 | G7: leeso0403 | H7: 별풍선 | I7: 152 | K7: 은플
A8: 7 | B8: 46283.856 | C8: 0:06:29 | D8: 빡빡.. | E8: chulbbak2 | F8: 체온 | G8: leeso0403 | H8: 별풍선 | I8: 10 | K8: 먹튀 전대표급이제 ㄹㅇ 온마
A9: 8 | B9: 46283.857 | C9: 0:07:45 | D9: [은]부엉 | E9: npeter7544 | F9: 체온 | G9: leeso0403 | H9: 별풍선 | I9: 10 | K9: 설명 모르겟고 온마
A10: 9 | B10: 46283.857 | C10: 0:08:11 | D10: 야뤠℃ | E10: lik9988 | F10: 체온 | G10: leeso0403 | H10: 별풍선 | I10: 100 | K10: 에라 모르겠다 온마
A11: 10 | B11: 46283.858 | C11: 0:09:31 | D11: [은]부엉 | E11: npeter7544 | F11: 체온 | G11: leeso0403 | H11: 별풍선 | I11: 10 | K11: 은채가 나라다 은채가 미래다 은플
A12: 11 | B12: 46283.858 | C12: 0:10:02 | D12: 야뤠℃ | E12: lik9988 | F12: 체온 | G12: leeso0403 | H12: 별풍선 | I12: 100 | K12: 은체
A13: 12 | B13: 46283.859 | C13: 0:10:54 | D13: [℃]천마당 | E13: jein1161 | F13: 체온 | G13: leeso0403 | H13: 별풍선 | I13: 10 | K13: 사람이 싫다 사퇴해라 온마
... A22: 21 | B22: 46283.862 | C22: 0:15:11 | D22: 후끼사 | E22: ross92 | F22: 체온 | G22: leeso0403 | H22: 별풍선 | I22: 345 | K22: 오니
A23: 22 | B23: 46283.863 | C23: 0:16:18 | D23: 후끼사 | E23: ross92 | F23: 체온 | G23: leeso0403 | H23: 별풍선 | I23: 335
A24: 23 | B24: 46283.864 | C24: 0:18:01 | D24: 늙짱구 | E24: gogosi369 | F24: 체온 | G24: leeso0403 | H24: 별풍선 | I24: 10 | K24: 은채
A25: 24 | B25: 46283.864 | C25: 0:18:09 | D25: 야뤠℃ | E25: lik9988 | F25: 체온 | G25: leeso0403 | H25: 별풍선 | I25: 1033 | K25: 온도
A26: 25 | B26: 46283.865 | C26: 0:19:30 | D26: [℃]천마당 | E26: jein1161 | F26: 체온 | G26: leeso0403 | H26: 별풍선 | I26: 10 | K26: 광대 올라가는게 싫다 온마
A27: 26 | B27: 46283.865 | C27: 0:19:40 | D27: [℃]천마당 | E27: jein1161 | F27: 체온 | G27: leeso0403 | H27: 별풍선 | I27: 10 | K27: 오늘 너무 못생겼다 온마
A28: 27 | B28: 46283.865 | C28: 0:19:49 | D28: [℃]천마당 | E28: jein1161 | F28: 체온 | G28: leeso0403 | H28: 별풍선 | I28: 10 | K28: 유전자 몰빵 자매한테 온마
A29: 28 | B29: 46283.867 | C29: 0:21:47 | D29: 자객* | E29: kimas019 | F29: 체온 | G29: leeso0403 | H29: 별풍선 | I29: 1470 | K29: 온 가져오슈
A30: 29 | B30: 46283.868 | C30: 0:23:20 | D30: [℃]천마당 | E30: jein1161 | F30: 체온 | G30: leeso0403 | H30: 별풍선 | I30: 100 | K30: 은버덕 힘내바 베비련한테 지면 마음아파
A31: 30 | B31: 46283.869 | C31: 0:25:10 | D31: 자객* | E31: kimas019 | F31: 체온 | G31: leeso0403 | H31: 별풍선 | I31: 30 | K31: 은채님은 아쉬우니 이거라도
A32: 31 | B32: 46283.87 | C32: 0:27:07 | D32: 정글on저튜브 | E32: dus5024 | F32: 체온 | G32: leeso0403 | H32: 별풍선 | I32: 2870 | K32: 공약개혜자 ㅇㅈ 온플
A33: 32 | B33: 46283.871 | C33: 0:27:49 | D33: 야뤠℃ | E33: lik9988 | F33: 체온 | G33: leeso0403 | H33: 별풍선 | I33: 2870 | K33: 묻
A34: 33 | B34: 46283.879 | C34: 0:39:19 | D34: 정글on저튜브 | E34: dus5024 | F34: 체온 | G34: leeso0403 | H34: 별풍선 | I34: 365 | K34: 신호탄 ㄱㄱ 첫어벤단 신호탄했엇는데 ㄹㅇ 그때 네이버시계켜놓고했는데 펑
A35: 34 | B35: 46283.88 | C35: 0:40:32 | D35: 야뤠℃ | E35: lik9988 | F35: 체온 | G35: leeso0403 | H35: 별풍선 | I35: 124
A36: 35 | B36: 46283.88 | C36: 0:40:44 | D36: 야뤠℃ | E36: lik9988 | F36: 체온 | G36: leeso0403 | H36: 별풍선 | I36: 119
A37: 36 | B37: 46283.88 | C37: 0:41:01 | D37: 야뤠℃ | E37: lik9988 | F37: 체온 | G37: leeso0403 | H37: 별풍선 | I37: 189
A38: 37 | B38: 46283.88 | C38: 0:41:06 | D38: 야뤠℃ | E38: lik9988 | F38: 체온 | G38: leeso0403 | H38: 별풍선 | I38: 266
A39: 38 | B39: 46283.881 | C39: 0:42:18 | D39: 야뤠℃ | E39: lik9988 | F39: 체온 | G39: leeso0403 | H39: 별풍선 | I39: 1472
A40: 39 | B40: 46283.883 | C40: 0:45:10 | D40: 야뤠℃ | E40: lik9988 | F40: 체온 | G40: leeso0403 | H40: 별풍선 | I40: 1312
A41: 40 | B41: 46283.887 | C41: 0:51:56 | D41: 야뤠℃ | E41: lik9988 | F41: 체온 | G41: leeso0403 | H41: 별풍선 | I41: 467 | K41: 은채 한번춰바라
A42: 41 | B42: 46283.889 | C42: 0:54:08 | D42: 정글on저튜브 | E42: dus5024 | F42: 체온 | G42: leeso0403 | H42: 별풍선 | I42: 122 | K42: 은채함해봐랑
A43: 42 | B43: 46283.889 | C43: 0:54:34 | D43: define# | E43: sejun513 | F43: 체온 | G43: leeso0403 | H43: 별풍선 | I43: 365 | K43: 지나가다 너무 이쁘셔서 처음 별풍선 충전해봅니다 리액션은 괜찮아요
A44: 43 | B44: 46283.89 | C44: 0:55:44 | D44: define# | E44: sejun513 | F44: 체온 | G44: leeso0403 | H44: 별풍선 | I44: 135 | K44: 블랙이요 ㅎㅎ
A45: 44 | B45: 46283.894 | C45: 1:01:15 | D45: 시간을구독중 | E45: hiswish11 | F45: 체온 | G45: leeso0403 | H45: 별풍선 | I45: 33 | K45: 은채핑 오랜만이네요 꾸벅
A46: 45 | B46: 46283.894 | C46: 1:01:35 | D46: 시간을구독중 | E46: hiswish11 | F46: 체온 | G46: leeso0403 | H46: 별풍선 | I46: 467 | K46: 은채신호탄구경좀
A47: 46 | B47: 46283.896 | C47: 1:04:51 | D47: 미르히로 | E47: lty9794 | F47: 체온 | G47: leeso0403 | H47: 별풍선 | I47: 1077 | K47: 간만에 한번 추는거보자ㅎ
A48: 47 | B48: 46283.897 | C48: 1:05:30 | D48: 야뤠℃ | E48: lik9988 | F48: 체온 | G48: leeso0403 | H48: 별풍선 | I48: 1077 | K48: 묻
...

Sheet 온플
A1: ID | B1: 시간 | C1: 방송시간 | D1: 닉네임 | E1: 아이디 | F1: 후원스트리머 | G1: 후원스트리머아이디 | H1: 풍선종류 | I1: 개수 | J1: 원플원 | K1: 채팅
A2: 2 | B2: 46283.853 | C2: 0:02:50 | D2: 뱀체온 | E2: ehdtjq3304 | F2: 체온 | G2: leeso0403 | H2: 별풍선 | I2: 100 | K2: 가즈아
A3: 21 | B3: 46283.862 | C3: 0:15:11 | D3: 후끼사 | E3: ross92 | F3: 체온 | G3: leeso0403 | H3: 별풍선 | I3: 345 | K3: 오니
A4: 22 | B4: 46283.863 | C4: 0:16:18 | D4: 후끼사 | E4: ross92 | F4: 체온 | G4: leeso0403 | H4: 별풍선 | I4: 335
A5: 24 | B5: 46283.864 | C5: 0:18:09 | D5: 야뤠℃ | E5: lik9988 | F5: 체온 | G5: leeso0403 | H5: 별풍선 | I5: 1033 | K5: 온도
A6: 28 | B6: 46283.867 | C6: 0:21:47 | D6: 자객* | E6: kimas019 | F6: 체온 | G6: leeso0403 | H6: 별풍선 | I6: 1470 | K6: 온 가져오슈
A7: 31 | B7: 46283.87 | C7: 0:27:07 | D7: 정글on저튜브 | E7: dus5024 | F7: 체온 | G7: leeso0403 | H7: 별풍선 | I7: 2870 | K7: 공약개혜자 ㅇㅈ 온플
A8: 32 | B8: 46283.871 | C8: 0:27:49 | D8: 야뤠℃ | E8: lik9988 | F8: 체온 | G8: leeso0403 | H8: 별풍선 | I8: 2870 | K8: 묻
A9: 33 | B9: 46283.879 | C9: 0:39:19 | D9: 정글on저튜브 | E9: dus5024 | F9: 체온 | G9: leeso0403 | H9: 별풍선 | I9: 365 | K9: 신호탄 ㄱㄱ 첫어벤단 신호탄했엇는데 ㄹㅇ 그때 네이버시계켜놓고했는데 펑
A10: 34 | B10: 46283.88 | C10: 0:40:32 | D10: 야뤠℃ | E10: lik9988 | F10: 체온 | G10: leeso0403 | H10: 별풍선 | I10: 124
A11: 35 | B11: 46283.88 | C11: 0:40:44 | D11: 야뤠℃ | E11: lik9988 | F11: 체온 | G11: leeso0403 | H11: 별풍선 | I11: 119
A12: 36 | B12: 46283.88 | C12: 0:41:01 | D12: 야뤠℃ | E12: lik9988 | F12: 체온 | G12: leeso0403 | H12: 별풍선 | I12: 189
A13: 37 | B13: 46283.88 | C13: 0:41:06 | D13: 야뤠℃ | E13: lik9988 | F13: 체온 | G13: leeso0403 | H13: 별풍선 | I13: 266
A14: 38 | B14: 46283.881 | C14: 0:42:18 | D14: 야뤠℃ | E14: lik9988 | F14: 체온 | G14: leeso0403 | H14: 별풍선 | I14: 1472
A15: 39 | B15: 46283.883 | C15: 0:45:10 | D15: 야뤠℃ | E15: lik9988 | F15: 체온 | G15: leeso0403 | H15: 별풍선 | I15: 1312
A16: 42 | B16: 46283.889 | C16: 0:54:34 | D16: define# | E16: sejun513 | F16: 체온 | G16: leeso0403 | H16: 별풍선 | I16: 365 | K16: 지나가다 너무 이쁘셔서 처음 별풍선 충전해봅니다 리액션은 괜찮아요
A17: 43 | B17: 46283.89 | C17: 0:55:44 | D17: define# | E17: sejun513 | F17: 체온 | G17: leeso0403 | H17: 별풍선 | I17: 135 | K17: 블랙이요 ㅎㅎ
A18: 46 | B18: 46283.896 | C18: 1:04:51 | D18: 미르히로 | E18: lty9794 | F18: 체온 | G18: leeso0403 | H18: 별풍선 | I18: 1077 | K18: 간만에 한번 추는거보자ㅎ
A19: 47 | B19: 46283.897 | C19: 1:05:30 | D19: 야뤠℃ | E19: lik9988 | F19: 체온 | G19: leeso0403 | H19: 별풍선 | I19: 1077 | K19: 묻
A20: 54 | B20: 46283.916 | C20: 1:32:38 | D20: 야뤠℃ | E20: lik9988 | F20: 체온 | G20: leeso0403 | H20: 별풍선 | I20: 1472 | K20: 불렀어??
A21: 56 | B21: 46283.919 | C21: 1:37:30 | D21: 야뤠℃ | E21: lik9988 | F21: 체온 | G21: leeso0403 | H21: 별풍선 | I21: 99
A22: 57 | B22: 46283.919 | C22: 1:37:33 | D22: 찡찡[빈]팬 | E22: twice3858 | F22: 체온 | G22: leeso0403 | H22: 별풍선 | I22: 100 | K22: 체온
A23: 65 | B23: 46283.927 | C23: 1:49:36 | D23: 정글on저튜브 | E23: dus5024 | F23: 체온 | G23: leeso0403 | H23: 별풍선 | I23: 365
A24: 66 | B24: 46283.928 | C24: 1:51:02 | D24: 야뤠℃ | E24: lik9988 | F24: 체온 | G24: leeso0403 | H24: 별풍선 | I24: 1414 | K24: 밥 마싯게먹고 2차전 가야지!!
A25: 67 | B25: 46283.929 | C25: 1:51:45 | D25: 조정간단발℃ | E25: 1234gung | F25: 체온 | G25: leeso0403 | H25: 룰렛 | I25: 370 | K25: 체온 (0.6%) 1196
A26: 69 | B26: 46283.933 | C26: 1:58:10 | D26: 야뤠℃ | E26: lik9988 | F26: 체온 | G26: leeso0403 | H26: 별풍선 | I26: 100 | K26: 천천히 먹어라ㅋㅋㅋㅋㅋ체온
A27: 74 | B27: 46283.953 | C27: 2:26:18 | D27: 이름이뭘까? | E27: tyu1103 | F27: 체온 | G27: leeso0403 | H27: 별풍선 | I27: 1014 | K27: 온
A28: 78 | B28: 46283.957 | C28: 2:32:39 | D28: 야뤠℃ | E28: lik9988 | F28: 체온 | G28: leeso0403 | H28: 별풍선 | I28: 3000 | K28: 딸깍
A29: 79 | B29: 46283.961 | C29: 2:37:11 | D29: 조정간단발℃ | E29: 1234gung | F29: 체온 | G29: leeso0403 | H29: 룰렛 | I29: 170 | K29: 체온 (1%) 301
A30: 80 | B30: 46283.964 | C30: 2:41:42 | D30: 야뤠℃ | E30: lik9988 | F30: 체온 | G30: leeso0403 | H30: 별풍선 | I30: 10000 | K30: 체온 드잡이가자
A31: 82 | B31: 46283.967 | C31: 2:45:49 | D31: 야뤠℃ | E31: lik9988 | F31: 체온 | G31: leeso0403 | H31: 별풍선 | I31: 10000
A32: 83 | B32: 46283.967 | C32: 2:47:10 | D32: 야뤠℃ | E32: lik9988 | F32: 체온 | G32: leeso0403 | H32: 별풍선 | I32: 1472 | K32: 찍어눌러 그냥ㅋㅋㅋㅋㅋ
A33: 86 | B33: 46283.973 | C33: 2:54:30 | D33: 비맞은강아쥐 | E33: tjdals3018 | F33: 체온 | G33: leeso0403 | H33: 별풍선 | I33: 33 | K33: 500
A34: 88 | B34: 46283.973 | C34: 2:55:47 | D34: 오베R | E34: nbearone1 | F34: 체온 | G34: leeso0403 | H34: 별풍선 | I34: 2870 | K34: 요거슨 온플
A35: 89 | B35: 46283.974 | C35: 2:56:51 | D35: 비맞은강아쥐 | E35: tjdals3018 | F35: 체온 | G35: leeso0403 | H35: 별풍선 | I35: 500 | K35: 온
A36: 92 | B36: 46283.976 | C36: 2:59:16 | D36: 오베R | E36: nbearone1 | F36: 체온 | G36: leeso0403 | H36: 별풍선 | I36: 365 | K36: 온
A37: 93 | B37: 46283.977 | C37: 3:00:17 | D37: 야뤠℃ | E37: lik9988 | F37: 체온 | G37: leeso0403 | H37: 별풍선 | I37: 3000 | K37: 온
A38: 95 | B38: 46283.977 | C38: 3:00:44 | D38: 오베R | E38: nbearone1 | F38: 체온 | G38: leeso0403 | H38: 별풍선 | I38: 99 | K38: 온
A39: 96 | B39: 46283.978 | C39: 3:02:56 | D39: 정글on저튜브 | E39: dus5024 | F39: 체온 | G39: leeso0403 | H39: 별풍선 | I39: 1058 | K39: 야르야르야르 온
A40: 98 | B40: 46283.98 | C40: 3:05:22 | D40: 비맞은강아쥐 | E40: tjdals3018 | F40: 체온 | G40: leeso0403 | H40: 별풍선 | I40: 10 | K40: 첫여왕 ㄷㄷ
...

Sheet 은플
A1: ID | B1: 시간 | C1: 방송시간 | D1: 닉네임 | E1: 아이디 | F1: 후원스트리머 | G1: 후원스트리머아이디 | H1: 풍선종류 | I1: 개수 | J1: 원플원 | K1: 채팅
A2: 1 | B2: 46283.851 | C2: 0:00:00 | D2: 차은돌 | E2: ckxoghksdlek | F2: 체온 | G2: leeso0403 | H2: 별풍선 | I2: 10 | K2: 은채
A3: 6 | B3: 46283.856 | C3: 0:06:27 | D3: [은]부엉 | E3: npeter7544 | F3: 체온 | G3: leeso0403 | H3: 별풍선 | I3: 152 | K3: 은플
A4: 10 | B4: 46283.858 | C4: 0:09:31 | D4: [은]부엉 | E4: npeter7544 | F4: 체온 | G4: leeso0403 | H4: 별풍선 | I4: 10 | K4: 은채가 나라다 은채가 미래다 은플
A5: 11 | B5: 46283.858 | C5: 0:10:02 | D5: 야뤠℃ | E5: lik9988 | F5: 체온 | G5: leeso0403 | H5: 별풍선 | I5: 100 | K5: 은체
A6: 13 | B6: 46283.859 | C6: 0:11:02 | D6: 싫은데. | E6: ehddjs92 | F6: 체온 | G6: leeso0403 | H6: 별풍선 | I6: 107 | K6: 은채님이 미래네요
A7: 18 | B7: 46283.861 | C7: 0:13:38 | D7: [은]부엉 | E7: npeter7544 | F7: 체온 | G7: leeso0403 | H7: 별풍선 | I7: 10 | K7: 광대 올려라 은플
A8: 23 | B8: 46283.864 | C8: 0:18:01 | D8: 늙짱구 | E8: gogosi369 | F8: 체온 | G8: leeso0403 | H8: 별풍선 | I8: 10 | K8: 은채
A9: 29 | B9: 46283.868 | C9: 0:23:20 | D9: [℃]천마당 | E9: jein1161 | F9: 체온 | G9: leeso0403 | H9: 별풍선 | I9: 100 | K9: 은버덕 힘내바 베비련한테 지면 마음아파
A10: 30 | B10: 46283.869 | C10: 0:25:10 | D10: 자객* | E10: kimas019 | F10: 체온 | G10: leeso0403 | H10: 별풍선 | I10: 30 | K10: 은채님은 아쉬우니 이거라도
A11: 40 | B11: 46283.887 | C11: 0:51:56 | D11: 야뤠℃ | E11: lik9988 | F11: 체온 | G11: leeso0403 | H11: 별풍선 | I11: 467 | K11: 은채 한번춰바라
A12: 41 | B12: 46283.889 | C12: 0:54:08 | D12: 정글on저튜브 | E12: dus5024 | F12: 체온 | G12: leeso0403 | H12: 별풍선 | I12: 122 | K12: 은채함해봐랑
A13: 44 | B13: 46283.894 | C13: 1:01:15 | D13: 시간을구독중 | E13: hiswish11 | F13: 체온 | G13: leeso0403 | H13: 별풍선 | I13: 33 | K13: 은채핑 오랜만이네요 꾸벅
... A18: 51 | B18: 46283.905 | C18: 1:17:28 | D18: 시간을구독중 | E18: hiswish11 | F18: 체온 | G18: leeso0403 | H18: 별풍선 | I18: 135 | K18: 은채핑
A19: 52 | B19: 46283.911 | C19: 1:26:00 | D19: coco1016 | E19: coco02160418 | F19: 체온 | G19: leeso0403 | H19: 별풍선 | I19: 467
A20: 55 | B20: 46283.919 | C20: 1:36:48 | D20: coco1016 | E20: coco02160418 | F20: 체온 | G20: leeso0403 | H20: 별풍선 | I20: 99
A21: 58 | B21: 46283.92 | C21: 1:38:14 | D21: 찡찡[빈]팬 | E21: twice3858 | F21: 체온 | G21: leeso0403 | H21: 별풍선 | I21: 100 | K21: 은채야 너도 해봐라
A22: 59 | B22: 46283.921 | C22: 1:40:13 | D22: coco1016 | E22: coco02160418 | F22: 체온 | G22: leeso0403 | H22: 별풍선 | I22: 200
A23: 60 | B23: 46283.922 | C23: 1:41:07 | D23: 야뤠℃ | E23: lik9988 | F23: 체온 | G23: leeso0403 | H23: 별풍선 | I23: 310 | K23: 은채
A24: 61 | B24: 46283.924 | C24: 1:44:04 | D24: [은]부엉 | E24: npeter7544 | F24: 체온 | G24: leeso0403 | H24: 별풍선 | I24: 467 | K24: 2연속 불발탄은 좀 그렇잖아?
A25: 62 | B25: 46283.924 | C25: 1:44:29 | D25: 야뤠℃ | E25: lik9988 | F25: 체온 | G25: leeso0403 | H25: 별풍선 | I25: 310 | K25: 은채
A26: 63 | B26: 46283.925 | C26: 1:46:29 | D26: 야뤠℃ | E26: lik9988 | F26: 체온 | G26: leeso0403 | H26: 별풍선 | I26: 122
A27: 64 | B27: 46283.925 | C27: 1:46:34 | D27: 야뤠℃ | E27: lik9988 | F27: 체온 | G27: leeso0403 | H27: 별풍선 | I27: 309
A28: 68 | B28: 46283.93 | C28: 1:53:34 | D28: 야뤠℃ | E28: lik9988 | F28: 체온 | G28: leeso0403 | H28: 별풍선 | I28: 1414 | K28: 못받을거같으니 맛나게 먹어라
A29: 70 | B29: 46283.953 | C29: 2:25:37 | D29: #그지빨빨이 | E29: hiddenmow5 | F29: 체온 | G29: leeso0403 | H29: 별풍선 | I29: 467 | K29: 은플
A30: 71 | B30: 46283.953 | C30: 2:26:02 | D30: #그지빨빨이 | E30: hiddenmow5 | F30: 체온 | G30: leeso0403 | H30: 별풍선 | I30: 122 | K30: 은플
A31: 72 | B31: 46283.953 | C31: 2:26:09 | D31: #그지빨빨이 | E31: hiddenmow5 | F31: 체온 | G31: leeso0403 | H31: 별풍선 | I31: 309 | K31: 은플
A32: 73 | B32: 46283.953 | C32: 2:26:16 | D32: #그지빨빨이 | E32: hiddenmow5 | F32: 체온 | G32: leeso0403 | H32: 별풍선 | I32: 310 | K32: 은플
A33: 75 | B33: 46283.954 | C33: 2:28:00 | D33: #그지빨빨이 | E33: hiddenmow5 | F33: 체온 | G33: leeso0403 | H33: 별풍선 | I33: 1030 | K33: 은플
A34: 76 | B34: 46283.955 | C34: 2:28:58 | D34: #그지빨빨이 | E34: hiddenmow5 | F34: 체온 | G34: leeso0403 | H34: 별풍선 | I34: 99 | K34: ㅋ
A35: 77 | B35: 46283.956 | C35: 2:30:56 | D35: #그지빨빨이 | E35: hiddenmow5 | F35: 체온 | G35: leeso0403 | H35: 별풍선 | I35: 123 | K35: 은플 ㅋ
A36: 81 | B36: 46283.965 | C36: 2:43:59 | D36: #그지빨빨이 | E36: hiddenmow5 | F36: 체온 | G36: leeso0403 | H36: 별풍선 | I36: 3000 | K36: ㅋㅋㅋ
A37: 84 | B37: 46283.971 | C37: 2:52:57 | D37: 정글on저튜브 | E37: dus5024 | F37: 체온 | G37: leeso0403 | H37: 별풍선 | I37: 191 | K37: 은채야 있어?
A38: 85 | B38: 46283.972 | C38: 2:53:31 | D38: 오베R | E38: nbearone1 | F38: 체온 | G38: leeso0403 | H38: 별풍선 | I38: 191 | K38: 없쪄 ㅇㅈㄹ
A39: 87 | B39: 46283.973 | C39: 2:55:05 | D39: 오베R | E39: nbearone1 | F39: 체온 | G39: leeso0403 | H39: 별풍선 | I39: 382 | K39: 은채 완전 기도 못피네 울지마 뚝!
... A45: 100 | B45: 46283.981 | C45: 3:06:38 | D45: 걸레왕점중 | E45: rupang3093 | F45: 체온 | G45: leeso0403 | H45: 별풍선 | I45: 1041 | K45: 은
A46: 101 | B46: 46283.982 | C46: 3:07:42 | D46: 걸레왕점중 | E46: rupang3093 | F46: 체온 | G46: leeso0403 | H46: 별풍선 | I46: 1077
A47: 102 | B47: 46283.982 | C47: 3:07:45 | D47: 걸레왕점중 | E47: rupang3093 | F47: 체온 | G47: leeso0403 | H47: 별풍선 | I47: 1077 | K47: 너
A48: 103 | B48: 46283.983 | C48: 3:09:21 | D48: 걸레왕점중 | E48: rupang3093 | F48: 체온 | G48: leeso0403 | H48: 별풍선 | I48: 1030
A49: 104 | B49: 46283.983 | C49: 3:09:24 | D49: 걸레왕점중 | E49: rupang3093 | F49: 체온 | G49: leeso0403 | H49: 별풍선 | I49: 1030 | K49: 대표는 더블링이 잘하네
...

Sheet 온마
A1: ID | B1: 시간 | C1: 방송시간 | D1: 닉네임 | E1: 아이디 | F1: 후원스트리머 | G1: 후원스트리머아이디 | H1: 풍선종류 | I1: 개수 | J1: 원플원 | K1: 채팅
A2: 3 | B2: 46283.854 | C2: 0:04:17 | D2: 차은돌 | E2: ckxoghksdlek | F2: 체온 | G2: leeso0403 | H2: 별풍선 | I2: 10 | K2: 30분 ㅅㅅ 온마
A3: 4 | B3: 46283.855 | C3: 0:05:08 | D3: #페라리 | E3: cash11111 | F3: 체온 | G3: leeso0403 | H3: 별풍선 | I3: 100 | K3: 온마
A4: 5 | B4: 46283.856 | C4: 0:05:57 | D4: 차은돌 | E4: ckxoghksdlek | F4: 체온 | G4: leeso0403 | H4: 별풍선 | I4: 10 | K4: 온마
A5: 7 | B5: 46283.856 | C5: 0:06:29 | D5: 빡빡.. | E5: chulbbak2 | F5: 체온 | G5: leeso0403 | H5: 별풍선 | I5: 10 | K5: 먹튀 전대표급이제 ㄹㅇ 온마
A6: 8 | B6: 46283.857 | C6: 0:07:45 | D6: [은]부엉 | E6: npeter7544 | F6: 체온 | G6: leeso0403 | H6: 별풍선 | I6: 10 | K6: 설명 모르겟고 온마
A7: 9 | B7: 46283.857 | C7: 0:08:11 | D7: 야뤠℃ | E7: lik9988 | F7: 체온 | G7: leeso0403 | H7: 별풍선 | I7: 100 | K7: 에라 모르겠다 온마
A8: 12 | B8: 46283.859 | C8: 0:10:54 | D8: [℃]천마당 | E8: jein1161 | F8: 체온 | G8: leeso0403 | H8: 별풍선 | I8: 10 | K8: 사람이 싫다 사퇴해라 온마
A9: 14 | B9: 46283.859 | C9: 0:11:03 | D9: [℃]천마당 | E9: jein1161 | F9: 체온 | G9: leeso0403 | H9: 별풍선 | I9: 10 | K9: 너라서 싫다 온마
A10: 17 | B10: 46283.861 | C10: 0:13:21 | D10: [℃]천마당 | E10: jein1161 | F10: 체온 | G10: leeso0403 | H10: 별풍선 | I10: 10 | K10: 광대 내려라 온마
A11: 19 | B11: 46283.861 | C11: 0:13:39 | D11: 빡빡.. | E11: chulbbak2 | F11: 체온 | G11: leeso0403 | H11: 별풍선 | I11: 10 | K11: 은채돌싱이엇네 개빡치네 온마
A12: 20 | B12: 46283.862 | C12: 0:14:50 | D12: [℃]천마당 | E12: jein1161 | F12: 체온 | G12: leeso0403 | H12: 별풍선 | I12: 10 | K12: 마이너스 처받고 먹을생각이드냐 온마
A13: 25 | B13: 46283.865 | C13: 0:19:30 | D13: [℃]천마당 | E13: jein1161 | F13: 체온 | G13: leeso0403 | H13: 별풍선 | I13: 10 | K13: 광대 올라가는게 싫다 온마
... A31: 169 | B31: 46284.059 | C31: 4:58:38 | D31: 부체온 | E31: akxh007 | F31: 체온 | G31: leeso0403 | H31: 별풍선 | I31: 500 | K31: 온마
A32: 총합 | I32: =SUM(I2:I31) -> 1228 | J32: =SUM(J2:J31) -> 0

Sheet 은마
A1: ID | B1: 시간 | C1: 방송시간 | D1: 닉네임 | E1: 아이디 | F1: 후원스트리머 | G1: 후원스트리머아이디 | H1: 풍선종류 | I1: 개수 | J1: 원플원 | K1: 채팅
A2: 15 | B2: 46283.86 | C2: 0:12:48 | D2: [℃]천마당 | E2: jein1161 | F2: 체온 | G2: leeso0403 | H2: 별풍선 | I2: 10 | K2: 바람 존나피네 은마 너도 싫다 이제
A3: 16 | B3: 46283.86 | C3: 0:13:00 | D3: 야뤠℃ | E3: lik9988 | F3: 체온 | G3: leeso0403 | H3: 별풍선 | I3: 10 | K3: 은마
A4: 53 | B4: 46283.913 | C4: 1:28:17 | D4: [은]부엉 | E4: npeter7544 | F4: 체온 | G4: leeso0403 | H4: 별풍선 | I4: 18 | K4: 유일한? 은마
A5: 총합 | I5: =SUM(I2:I4) -> 38 | J5: =SUM(J2:J4) -> 0

Sheet 전체 후원자 순위
A1: 후원목록 | 후원자별 총 후원 개수
A2: 순위 | B2: 닉네임 | C2: 아이디 | D2: 총 후원 개수 | E2: 후원 건수 | F2: 공통공약
A3: 1 | B3: 야뤠℃ | C3: lik9988 | D3: =SUMIF(후원목록!$E$2:$E$174,C3,후원목록!$I$2:$I$174) -> 59407 | E3: =COUNTIF(후원목록!$E$2:$E$174,C3) -> 36 | F3: 자매 영상 방셀(완료)
A4: 2 | B4: 걸레왕점중 | C4: rupang3093 | D4: =SUMIF(후원목록!$E$2:$E$174,C4,후원목록!$I$2:$I$174) -> 18591 | E4: =COUNTIF(후원목록!$E$2:$E$174,C4) -> 17 | F4: 자매 영상 방셀(완료)
A5: 3 | B5: 룰루놀롤 | C5: sting0912 | D5: =SUMIF(후원목록!$E$2:$E$174,C5,후원목록!$I$2:$I$174) -> 15569 | E5: =COUNTIF(후원목록!$E$2:$E$174,C5) -> 11 | F5: 자매 영상 방셀(완료)
A6: 4 | B6: 정글on저튜브 | C6: dus5024 | D6: =SUMIF(후원목록!$E$2:$E$174,C6,후원목록!$I$2:$I$174) -> 7273 | E6: =COUNTIF(후원목록!$E$2:$E$174,C6) -> 9 | F6: X
A7: 5 | B7: 오베R | C7: nbearone1 | D7: =SUMIF(후원목록!$E$2:$E$174,C7,후원목록!$I$2:$I$174) -> 7051 | E7: =COUNTIF(후원목록!$E$2:$E$174,C7) -> 14 | F7: X
A8: 6 | B8: #그지빨빨이 | C8: hiddenmow5 | D8: =SUMIF(후원목록!$E$2:$E$174,C8,후원목록!$I$2:$I$174) -> 5460 | E8: =COUNTIF(후원목록!$E$2:$E$174,C8) -> 8 | F8: X
A9: 7 | B9: 지우- | C9: wldn4422 | D9: =SUMIF(후원목록!$E$2:$E$174,C9,후원목록!$I$2:$I$174) -> 2996 | E9: =COUNTIF(후원목록!$E$2:$E$174,C9) -> 2 | F9: X
A10: 8 | B10: 부체온 | C10: akxh007 | D10: =SUMIF(후원목록!$E$2:$E$174,C10,후원목록!$I$2:$I$174) -> 2963 | E10: =COUNTIF(후원목록!$E$2:$E$174,C10) -> 7 | F10: X
A11: 9 | B11: 귀염둥이파덕 | C11: tpgns4565 | D11: =SUMIF(후원목록!$E$2:$E$174,C11,후원목록!$I$2:$I$174) -> 2277 | E11: =COUNTIF(후원목록!$E$2:$E$174,C11) -> 2 | F11: X
A12: 10 | B12: 미르히로 | C12: lty9794 | D12: =SUMIF(후원목록!$E$2:$E$174,C12,후원목록!$I$2:$I$174) -> 1544 | E12: =COUNTIF(후원목록!$E$2:$E$174,C12) -> 2 | F12: X
A13: 11 | B13: 자객* | C13: kimas019 | D13: =SUMIF(후원목록!$E$2:$E$174,C13,후원목록!$I$2:$I$174) -> 1500 | E13: =COUNTIF(후원목록!$E$2:$E$174,C13) -> 2 | F13: X
A14: 12 | B14: ΘωΘ;;쿠궁 | C14: wnahd0918 | D14: =SUMIF(후원목록!$E$2:$E$174,C14,후원목록!$I$2:$I$174) -> 1136 | E14: =COUNTIF(후원목록!$E$2:$E$174,C14) -> 4 | F14: X
... A30: 28 | B30: 늙짱구 | C30: gogosi369 | D30: =SUMIF(후원목록!$E$2:$E$174,C30,후원목록!$I$2:$I$174) -> 10 | E30: =COUNTIF(후원목록!$E$2:$E$174,C30) -> 1 | F30: X
A31: 합계 | B31: 28명 | D31: =SUM(D3:D30) -> 132975 | E31: =SUM(E3:E30) -> 173

Sheet 온플 후원자 순위
A1: 온플단 | 후원자별 총 후원 개수
A2: 순위 | B2: 닉네임 | C2: 아이디 | D2: 총 후원 개수 | E2: 후원 건수 | F2: 온플단공약
A3: 1 | B3: 야뤠℃ | C3: lik9988 | D3: =SUMIF(온플!$E$2:$E$57,C3,온플!$I$2:$I$57) -> 53165 | E3: =COUNTIF(온플!$E$2:$E$57,C3) -> 25 | F3: 식데
A4: 2 | B4: 정글on저튜브 | C4: dus5024 | D4: =SUMIF(온플!$E$2:$E$57,C4,온플!$I$2:$I$57) -> 5735 | E4: =COUNTIF(온플!$E$2:$E$57,C4) -> 5 | F4: 고화질 움짤방셀 8장 + 냠냠권(알잘딱)
A5: 3 | B5: 오베R | C5: nbearone1 | D5: =SUMIF(온플!$E$2:$E$57,C5,온플!$I$2:$I$57) -> 3334 | E5: =COUNTIF(온플!$E$2:$E$57,C5) -> 3 | F5: 고화질 움짤방셀 8장
A6: 4 | B6: 지우- | C6: wldn4422 | D6: =SUMIF(온플!$E$2:$E$57,C6,온플!$I$2:$I$57) -> 2996 | E6: =COUNTIF(온플!$E$2:$E$57,C6) -> 2 | F6: 고화질 움짤방셀 8장 + 냠냠권(알잘딱)
A7: 5 | B7: 자객* | C7: kimas019 | D7: =SUMIF(온플!$E$2:$E$57,C7,온플!$I$2:$I$57) -> 1470 | E7: =COUNTIF(온플!$E$2:$E$57,C7) -> 1 | F7: 움짤방셀 4장
A8: 6 | B8: 미르히로 | C8: lty9794 | D8: =SUMIF(온플!$E$2:$E$57,C8,온플!$I$2:$I$57) -> 1077 | E8: =COUNTIF(온플!$E$2:$E$57,C8) -> 1 | F8: 공통 고화질 움짤방셀 1장
A9: 7 | B9: 이름이뭘까? | C9: tyu1103 | D9: =SUMIF(온플!$E$2:$E$57,C9,온플!$I$2:$I$57) -> 1014 | E9: =COUNTIF(온플!$E$2:$E$57,C9) -> 1 | F9: 공통 고화질 움짤방셀 1장
A10: 8 | B10: 부체온 | C10: akxh007 | D10: =SUMIF(온플!$E$2:$E$57,C10,온플!$I$2:$I$57) -> 743 | E10: =COUNTIF(온플!$E$2:$E$57,C10) -> 2 | F10: 소음단 핀볼 치킨 7코
A11: 9 | B11: 후끼사 | C11: ross92 | D11: =SUMIF(온플!$E$2:$E$57,C11,온플!$I$2:$I$57) -> 680 | E11: =COUNTIF(온플!$E$2:$E$57,C11) -> 2 | F11: 소음단 핀볼 치킨 6코
A12: 10 | B12: ΘωΘ;;쿠궁 | C12: wnahd0918 | D12: =SUMIF(온플!$E$2:$E$57,C12,온플!$I$2:$I$57) -> 548 | E12: =COUNTIF(온플!$E$2:$E$57,C12) -> 2 | F12: 소음단 핀볼 치킨 5코
A13: 11 | B13: 비맞은강아쥐 | C13: tjdals3018 | D13: =SUMIF(온플!$E$2:$E$57,C13,온플!$I$2:$I$57) -> 543 | E13: =COUNTIF(온플!$E$2:$E$57,C13) -> 3 | F13: 소음단 핀볼 치킨 5코
A14: 12 | B14: 조정간단발℃ | C14: 1234gung | D14: =SUMIF(온플!$E$2:$E$57,C14,온플!$I$2:$I$57) -> 540 | E14: =COUNTIF(온플!$E$2:$E$57,C14) -> 2 | F14: 소음단 핀볼 치킨 5코
... A19: 17 | B19: [℃]천마당 | C19: jein1161 | D19: =SUMIF(온플!$E$2:$E$57,C19,온플!$I$2:$I$57) -> 10 | E19: =COUNTIF(온플!$E$2:$E$57,C19) -> 1 | F19: X
A20: 합계 | B20: 17명 | D20: =SUM(D3:D19) -> 72575 | E20: =SUM(E3:E19) -> 56

Sheet 은플 후원자 순위
A1: 은플단 | 후원자별 총 후원 개수
A2: 순위 | B2: 닉네임 | C2: 아이디 | D2: 총 후원 개수 | E2: 후원 건수 | F2: 은플단 공약
A3: 1 | B3: 걸레왕점중 | C3: rupang3093 | D3: =SUMIF(은플!$E$2:$E$85,C3,은플!$I$2:$I$85) -> 18591 | E3: =COUNTIF(은플!$E$2:$E$85,C3) -> 17 | F3: 인생네컷 + 움짤 4장 방셀 + (알잘딱)
A4: 2 | B4: 룰루놀롤 | C4: sting0912 | D4: =SUMIF(은플!$E$2:$E$85,C4,은플!$I$2:$I$85) -> 15569 | E4: =COUNTIF(은플!$E$2:$E$85,C4) -> 11 | F4: 인생네컷 + 움짤 4장 방셀 + (알잘딱)
A5: 3 | B5: 야뤠℃ | C5: lik9988 | D5: =SUMIF(은플!$E$2:$E$85,C5,은플!$I$2:$I$85) -> 6132 | E5: =COUNTIF(은플!$E$2:$E$85,C5) -> 9 | F5: 움짤방셀 4장
A6: 4 | B6: #그지빨빨이 | C6: hiddenmow5 | D6: =SUMIF(은플!$E$2:$E$85,C6,은플!$I$2:$I$85) -> 5460 | E6: =COUNTIF(은플!$E$2:$E$85,C6) -> 8 | F6: 움짤방셀 4장
A7: 5 | B7: 오베R | C7: nbearone1 | D7: =SUMIF(은플!$E$2:$E$85,C7,은플!$I$2:$I$85) -> 3677 | E7: =COUNTIF(은플!$E$2:$E$85,C7) -> 7 | F7: 움짤방셀 4장
A8: 6 | B8: 귀염둥이파덕 | C8: tpgns4565 | D8: =SUMIF(은플!$E$2:$E$85,C8,은플!$I$2:$I$85) -> 2277 | E8: =COUNTIF(은플!$E$2:$E$85,C8) -> 2 | F8: 공통쪽셀
A9: 7 | B9: 부체온 | C9: akxh007 | D9: =SUMIF(은플!$E$2:$E$85,C9,은플!$I$2:$I$85) -> 1720 | E9: =COUNTIF(은플!$E$2:$E$85,C9) -> 4 | F9: 공통쪽셀
A10: 8 | B10: 정글on저튜브 | C10: dus5024 | D10: =SUMIF(은플!$E$2:$E$85,C10,은플!$I$2:$I$85) -> 1538 | E10: =COUNTIF(은플!$E$2:$E$85,C10) -> 4 | F10: 공통쪽셀
A11: 9 | B11: 시간을구독중 | C11: hiswish11 | D11: =SUMIF(은플!$E$2:$E$85,C11,은플!$I$2:$I$85) -> 1005 | E11: =COUNTIF(은플!$E$2:$E$85,C11) -> 4 | F11: 공통쪽셀
A12: 10 | B12: coco1016 | C12: coco02160418 | D12: =SUMIF(은플!$E$2:$E$85,C12,은플!$I$2:$I$85) -> 766 | E12: =COUNTIF(은플!$E$2:$E$85,C12) -> 3 | F12: 공통쪽셀
A13: 11 | B13: [은]부엉 | C13: npeter7544 | D13: =SUMIF(은플!$E$2:$E$85,C13,은플!$I$2:$I$85) -> 639 | E13: =COUNTIF(은플!$E$2:$E$85,C13) -> 4 | F13: 공통쪽셀
A14: 12 | B14: ΘωΘ;;쿠궁 | C14: wnahd0918 | D14: =SUMIF(은플!$E$2:$E$85,C14,은플!$I$2:$I$85) -> 588 | E14: =COUNTIF(은플!$E$2:$E$85,C14) -> 2 | F14: 공통쪽셀
... A22: 20 | B22: 늙짱구 | C22: gogosi369 | D22: =SUMIF(은플!$E$2:$E$85,C22,은플!$I$2:$I$85) -> 10 | E22: =COUNTIF(은플!$E$2:$E$85,C22) -> 1 | F22: x
A23: 합계 | B23: 20명 | D23: =SUM(D3:D22) -> 59134 | E23: =SUM(E3:E22) -> 84

Sheet 온마 후원자 순위
A1: 온마 | 후원자별 총 후원 개수
A2: 순위 | B2: 닉네임 | C2: 아이디 | D2: 총 후원 개수 | E2: 후원 건수
A3: 1 | B3: 부체온 | C3: akxh007 | D3: =SUMIF(온마!$E$2:$E$31,C3,온마!$I$2:$I$31) -> 500 | E3: =COUNTIF(온마!$E$2:$E$31,C3) -> 1
A4: 2 | B4: [℃]천마당 | C4: jein1161 | D4: =SUMIF(온마!$E$2:$E$31,C4,온마!$I$2:$I$31) -> 428 | E4: =COUNTIF(온마!$E$2:$E$31,C4) -> 17
A5: 3 | B5: #페라리 | C5: cash11111 | D5: =SUMIF(온마!$E$2:$E$31,C5,온마!$I$2:$I$31) -> 100 | E5: =COUNTIF(온마!$E$2:$E$31,C5) -> 1
A6: 4 | B6: 야뤠℃ | C6: lik9988 | D6: =SUMIF(온마!$E$2:$E$31,C6,온마!$I$2:$I$31) -> 100 | E6: =COUNTIF(온마!$E$2:$E$31,C6) -> 1
A7: 5 | B7: 오베R | C7: nbearone1 | D7: =SUMIF(온마!$E$2:$E$31,C7,온마!$I$2:$I$31) -> 40 | E7: =COUNTIF(온마!$E$2:$E$31,C7) -> 4
A8: 6 | B8: 빡빡.. | C8: chulbbak2 | D8: =SUMIF(온마!$E$2:$E$31,C8,온마!$I$2:$I$31) -> 20 | E8: =COUNTIF(온마!$E$2:$E$31,C8) -> 2
A9: 7 | B9: 차은돌 | C9: ckxoghksdlek | D9: =SUMIF(온마!$E$2:$E$31,C9,온마!$I$2:$I$31) -> 20 | E9: =COUNTIF(온마!$E$2:$E$31,C9) -> 2
A10: 8 | B10: [은]부엉 | C10: npeter7544 | D10: =SUMIF(온마!$E$2:$E$31,C10,온마!$I$2:$I$31) -> 20 | E10: =COUNTIF(온마!$E$2:$E$31,C10) -> 2
A11: 합계 | B11: 8명 | D11: =SUM(D3:D10) -> 1228 | E11: =SUM(E3:E10) -> 30

Sheet 은마 후원자 순위
A1: 은마 | 후원자별 총 후원 개수
A2: 순위 | B2: 닉네임 | C2: 아이디 | D2: 총 후원 개수 | E2: 후원 건수
A3: 1 | B3: [은]부엉 | C3: npeter7544 | D3: =SUMIF(은마!$E$2:$E$4,C3,은마!$I$2:$I$4) -> 18 | E3: =COUNTIF(은마!$E$2:$E$4,C3) -> 1
A4: 2 | B4: [℃]천마당 | C4: jein1161 | D4: =SUMIF(은마!$E$2:$E$4,C4,은마!$I$2:$I$4) -> 10 | E4: =COUNTIF(은마!$E$2:$E$4,C4) -> 1
A5: 3 | B5: 야뤠℃ | C5: lik9988 | D5: =SUMIF(은마!$E$2:$E$4,C5,은마!$I$2:$I$4) -> 10 | E5: =COUNTIF(은마!$E$2:$E$4,C5) -> 1
A6: 합계 | B6: 3명 | D6: =SUM(D3:D5) -> 38 | E6: =SUM(E3:E5) -> 3
